{"uuid": "f924721d-4e1f-4396-b19b-303bbd99ff21", "children": ["f5030a56-71b5-480b-9e95-bedfbd888401", "cf3e7649-ad98-471f-aa68-f4d60e2a6dfb", "fdcaa21d-838e-4e12-9f9c-4c67cfc76f76", "72c7565f-0bc7-41a0-9618-df9b10f90c36"], "befores": [{"name": "_xunit_setup_class_fixture_TestHelloWorldService", "status": "failed", "statusDetails": {"message": "Failed: Service failed to start within expected time\n", "trace": "  File \"C:\\Python314\\Lib\\site-packages\\pluggy\\_callers.py\", line 38, in run_old_style_hookwrapper\n    res = yield\n          ^^^^^\n  File \"C:\\Python314\\Lib\\site-packages\\pluggy\\_callers.py\", line 139, in _multicall\n    teardown.throw(exception)\n    ~~~~~~~~~~~~~~^^^^^^^^^^^\n  File \"C:\\Python314\\Lib\\site-packages\\pluggy\\_callers.py\", line 53, in run_old_style_hookwrapper\n    return result.get_result()\n           ~~~~~~~~~~~~~~~~~^^\n  File \"C:\\Python314\\Lib\\site-packages\\pluggy\\_result.py\", line 103, in get_result\n    raise exc.with_traceback(tb)\n  File \"C:\\Python314\\Lib\\site-packages\\pluggy\\_callers.py\", line 38, in run_old_style_hookwrapper\n    res = yield\n          ^^^^^\n  File \"C:\\Python314\\Lib\\site-packages\\pluggy\\_callers.py\", line 121, in _multicall\n    res = hook_impl.function(*args)\n  File \"C:\\Python314\\Lib\\site-packages\\_pytest\\fixtures.py\", line 1123, in pytest_fixture_setup\n    result = call_fixture_func(fixturefunc, request, kwargs)\n  File \"C:\\Python314\\Lib\\site-packages\\_pytest\\fixtures.py\", line 895, in call_fixture_func\n    fixture_result = next(generator)\n  File \"C:\\Python314\\Lib\\site-packages\\_pytest\\python.py\", line 856, in xunit_setup_class_fixture\n    _call_with_optional_argument(func, self.obj)\n    ~~~~~~~~~~~~~~~~~~~~~~~~~~~~^^^^^^^^^^^^^^^^\n  File \"C:\\Python314\\Lib\\site-packages\\_pytest\\python.py\", line 777, in _call_with_optional_argument\n    func(arg)\n    ~~~~^^^^^\n  File \"D:\\jinkins-ci-demo\\tests\\test_app.py\", line 25, in setup_class\n    cls.retry_delay = 1\n        ^^^^^^^^^^^^^^^\n  File \"C:\\Python314\\Lib\\site-packages\\_pytest\\outcomes.py\", line 198, in fail\n    raise Failed(msg=reason, pytrace=pytrace)\n"}, "start": 1760527416210, "stop": 1760527599212}], "start": 1760527416210, "stop": 1760527599300}